Workbook

Sheet Sources
A1: By sq. m of roofed area
A2: Year | B2: Source | C2: Party | D2: Type | E2: Region | F2: Unit value
A3: 2015 | B3: RM 286-2015-VIVIENDA | C3: Walls | D3: C | E3: Costa | F3: 200.99
A4: 2015 | B4: RM 286-2015-VIVIENDA | C4: Roof | D4: C | E4: Costa | F4: 148.26
A5: 2015 | B5: RM 286-2015-VIVIENDA | C5: Floor | D5: G | E5: Costa | F5: 34.13
A6: 2015 | B6: RM 286-2015-VIVIENDA | C6: Door and roof | D6: F | E6: Costa | F6: 47.11
A7: 2015 | B7: RM 286-2015-VIVIENDA | C7: Coating | D7: F | E7: Costa | F7: 55.41
A8: 2015 | B8: RM 286-2015-VIVIENDA | C8: Toilet | D8: C | E8: Costa | F8: 47.15
A9: 2015 | B9: RM 286-2015-VIVIENDA | C9: Electricals | D9: E | E9: Costa | F9: 53.56
A10: 2015 | B10: RM 286-2015-VIVIENDA | C10: Walls | D10: C | E10: Sierra | F10: 217.76
A11: 2015 | B11: RM 286-2015-VIVIENDA | C11: Roof | D11: C | E11: Sierra | F11: 126.2
A12: 2015 | B12: RM 286-2015-VIVIENDA | C12: Floor | D12: G | E12: Sierra | F12: 41.6
A13: 2015 | B13: RM 286-2015-VIVIENDA | C13: Door and window | D13: F | E13: Sierra | F13: 44.54
A14: 2015 | B14: RM 286-2015-VIVIENDA | C14: Coating | D14: F | E14: Sierra | F14: 63.02
... A107: 2019 | B107: RM 351-2019-VIVIENDA | C107: Electricals | D107: E | E107: Selva | F107: 59.98

Sheet CalcXsize
A1: Costa | C1: Unit Cost | D1: Area | E1: Cost | G1: Costa | I1: Unit Cost | J1: Area | K1: Cost | M1: Costa | O1: Unit Cost | P1: Area | Q1: Cost | S1: Costa | U1: Unit Cost | V1: Area | W1: Cost | Y1: Costa | AA1: Unit Cost | AB1: Area | AC1: Cost
A2: 2015 | B2: Walls | C2: =Sources!F3 -> 200.99 | D2: =2.7*2.7 + (2.7*2.7*0.3) -> 9.477 | E2: =C2*D2 -> 1904.7822 | G2: 2016 | H2: Walls | I2: =Sources!F24 -> 207.02 | J2: =2.7*2.7 + (2.7*2.7*0.3) -> 9.477 | K2: =I2*J2 -> 1961.9285 | M2: 2017 | N2: Walls | O2: =Sources!F45 -> 213.23 | P2: =2.7*2.7 + (2.7*2.7*0.3) -> 9.477 | Q2: =O2*P2 -> 2020.7807 | S2: 2018 | T2: Walls | U2: =Sources!F66 -> 219.63 | V2: =2.7*2.7 + (2.7*2.7*0.3) -> 9.477 | W2: =U2*V2 -> 2081.4335 | Y2: 2019 | Z2: Walls | AA2: =Sources!F87 -> 224.24 | AB2: =2.7*2.7 + (2.7*2.7*0.3) -> 9.477 | AC2: =AA2*AB2 -> 2125.1225
B3: Roof | C3: =Sources!F4 -> 148.26 | D3: =2.7*2.7 + (2.7*2.7*0.3) -> 9.477 | E3: =C3*D3 -> 1405.06 | H3: Roof | I3: =Sources!F25 -> 152.71 | J3: =2.7*2.7 + (2.7*2.7*0.3) -> 9.477 | K3: =I3*J3 -> 1447.2327 | N3: Roof | O3: =Sources!F46 -> 157.29 | P3: =2.7*2.7 + (2.7*2.7*0.3) -> 9.477 | Q3: =O3*P3 -> 1490.6373 | T3: Roof | U3: =Sources!F67 -> 162.01 | V3: =2.7*2.7 + (2.7*2.7*0.3) -> 9.477 | W3: =U3*V3 -> 1535.3688 | Z3: Roof | AA3: =Sources!F88 -> 165.41 | AB3: =2.7*2.7 + (2.7*2.7*0.3) -> 9.477 | AC3: =AA3*AB3 -> 1567.5906
B4: Floor | C4: =Sources!F5 -> 34.13 | D4: =2.7*2.7 + (2.7*2.7*0.3) -> 9.477 | E4: =C4*D4 -> 323.45001 | H4: Floor | I4: =Sources!F26 -> 35.16 | J4: =2.7*2.7 + (2.7*2.7*0.3) -> 9.477 | K4: =I4*J4 -> 333.21132 | N4: Floor | O4: =Sources!F47 -> 36.21 | P4: =2.7*2.7 + (2.7*2.7*0.3) -> 9.477 | Q4: =O4*P4 -> 343.16217 | T4: Floor | U4: =Sources!F68 -> 37.3 | V4: =2.7*2.7 + (2.7*2.7*0.3) -> 9.477 | W4: =U4*V4 -> 353.4921 | Z4: Floor | AA4: =Sources!F89 -> 38.08 | AB4: =2.7*2.7 + (2.7*2.7*0.3) -> 9.477 | AC4: =AA4*AB4 -> 360.88416
B5: Door and roof | C5: =Sources!F6 -> 47.11 | D5: =2.7*2.7 + (2.7*2.7*0.3) -> 9.477 | E5: =C5*D5 -> 446.46147 | H5: Door and roof | I5: =Sources!F27 -> 48.53 | J5: =2.7*2.7 + (2.7*2.7*0.3) -> 9.477 | K5: =I5*J5 -> 459.91881 | N5: Door and roof | O5: =Sources!F48 -> 49.98 | P5: =2.7*2.7 + (2.7*2.7*0.3) -> 9.477 | Q5: =O5*P5 -> 473.66046 | T5: Door and roof | U5: =Sources!F69 -> 51.48 | V5: =2.7*2.7 + (2.7*2.7*0.3) -> 9.477 | W5: =U5*V5 -> 487.87596 | Z5: Door and roof | AA5: =Sources!F90 -> 52.56 | AB5: =2.7*2.7 + (2.7*2.7*0.3) -> 9.477 | AC5: =AA5*AB5 -> 498.11112
B6: Coating | C6: =Sources!F7 -> 55.41 | D6: =2.7*2.7 + (2.7*2.7*0.3) -> 9.477 | E6: =C6*D6 -> 525.12057 | H6: Coating | I6: =Sources!F28 -> 57.07 | J6: =2.7*2.7 + (2.7*2.7*0.3) -> 9.477 | K6: =I6*J6 -> 540.85239 | N6: Coating | O6: =Sources!F49 -> 58.78 | P6: =2.7*2.7 + (2.7*2.7*0.3) -> 9.477 | Q6: =O6*P6 -> 557.05806 | T6: Coating | U6: =Sources!F70 -> 60.54 | V6: =2.7*2.7 + (2.7*2.7*0.3) -> 9.477 | W6: =U6*V6 -> 573.73758 | Z6: Coating | AA6: =Sources!F91 -> 61.82 | AB6: =2.7*2.7 + (2.7*2.7*0.3) -> 9.477 | AC6: =AA6*AB6 -> 585.86814
B7: Toilet | C7: =Sources!F8 -> 47.15 | D7: =2.7*2.7 + (2.7*2.7*0.3) -> 9.477 | E7: =C7*D7 -> 446.84055 | H7: Toilet | I7: =Sources!F29 -> 48.56 | J7: =2.7*2.7 + (2.7*2.7*0.3) -> 9.477 | K7: =I7*J7 -> 460.20312 | N7: Toilet | O7: =Sources!F50 -> 50.02 | P7: =2.7*2.7 + (2.7*2.7*0.3) -> 9.477 | Q7: =O7*P7 -> 474.03954 | T7: Toilet | U7: =Sources!F71 -> 51.52 | V7: =2.7*2.7 + (2.7*2.7*0.3) -> 9.477 | W7: =U7*V7 -> 488.25504 | Z7: Toilet | AA7: =Sources!F92 -> 52.6 | AB7: =2.7*2.7 + (2.7*2.7*0.3) -> 9.477 | AC7: =AA7*AB7 -> 498.4902
B8: Electricals | C8: =Sources!F9 -> 53.56 | D8: =2.7*2.7 + (2.7*2.7*0.3) -> 9.477 | E8: =C8*D8 -> 507.58812 | H8: Electricals | I8: =Sources!F30 -> 55.17 | J8: =2.7*2.7 + (2.7*2.7*0.3) -> 9.477 | K8: =I8*J8 -> 522.84609 | N8: Electricals | O8: =Sources!F51 -> 56.82 | P8: =2.7*2.7 + (2.7*2.7*0.3) -> 9.477 | Q8: =O8*P8 -> 538.48314 | T8: Electricals | U8: =Sources!F72 -> 58.53 | V8: =2.7*2.7 + (2.7*2.7*0.3) -> 9.477 | W8: =U8*V8 -> 554.68881 | Z8: Electricals | AA8: =Sources!F93 -> 59.76 | AB8: =2.7*2.7 + (2.7*2.7*0.3) -> 9.477 | AC8: =AA8*AB8 -> 566.34552
E9: =SUM(E2:E8) -> 5559.303 | F9: =E9/D8 -> 586.61 | K9: =SUM(K2:K8) -> 5726.1929 | Q9: =SUM(Q2:Q8) -> 5897.8214 | W9: =SUM(W2:W8) -> 6074.8518 | AC9: =SUM(AC2:AC8) -> 6202.4122
F10: =F9*2 -> 1173.22
A11: Sierra | C11: Unit Cost | D11: Area | E11: Cost | G11: Sierra | I11: Unit Cost | J11: Area | K11: Cost | M11: Sierra | O11: Unit Cost | P11: Area | Q11: Cost | S11: Sierra | U11: Unit Cost | V11: Area | W11: Cost | Y11: Sierra | AA11: Unit Cost | AB11: Area | AC11: Cost
A12: 2015 | B12: Walls | C12: =Sources!F10 -> 217.76 | D12: =2.7*2.7 + (2.7*2.7*0.3) -> 9.477 | E12: =C12*D12 -> 2063.7115 | G12: 2016 | H12: Walls | I12: =Sources!F31 -> 224.29 | J12: =2.7*2.7 + (2.7*2.7*0.3) -> 9.477 | K12: =I12*J12 -> 2125.5963 | M12: 2017 | N12: Walls | O12: =Sources!F52 -> 231.02 | P12: =2.7*2.7 + (2.7*2.7*0.3) -> 9.477 | Q12: =O12*P12 -> 2189.3765 | S12: 2018 | T12: Walls | U12: =Sources!F73 -> 237.95 | V12: =2.7*2.7 + (2.7*2.7*0.3) -> 9.477 | W12: =U12*V12 -> 2255.0521 | Y12: 2019 | Z12: Walls | AA12: =Sources!F94 -> 242.95 | AB12: =2.7*2.7 + (2.7*2.7*0.3) -> 9.477 | AC12: =AA12*AB12 -> 2302.4371
B13: Roof | C13: =Sources!F11 -> 126.2 | D13: =2.7*2.7 + (2.7*2.7*0.3) -> 9.477 | E13: =C13*D13 -> 1195.9974 | H13: Roof | I13: =Sources!F32 -> 129.99 | J13: =2.7*2.7 + (2.7*2.7*0.3) -> 9.477 | K13: =I13*J13 -> 1231.9152 | N13: Roof | O13: =Sources!F53 -> 133.89 | P13: =2.7*2.7 + (2.7*2.7*0.3) -> 9.477 | Q13: =O13*P13 -> 1268.8755 | T13: Roof | U13: =Sources!F74 -> 137.9 | V13: =2.7*2.7 + (2.7*2.7*0.3) -> 9.477 | W13: =U13*V13 -> 1306.8783 | Z13: Roof | AA13: =Sources!F95 -> 140.8 | AB13: =2.7*2.7 + (2.7*2.7*0.3) -> 9.477 | AC13: =AA13*AB13 -> 1334.3616
B14: Floor | C14: =Sources!F12 -> 41.6 | D14: =2.7*2.7 + (2.7*2.7*0.3) -> 9.477 | E14: =C14*D14 -> 394.2432 | H14: Floor | I14: =Sources!F33 -> 42.85 | J14: =2.7*2.7 + (2.7*2.7*0.3) -> 9.477 | K14: =I14*J14 -> 406.08945 | N14: Floor | O14: =Sources!F54 -> 44.14 | P14: =2.7*2.7 + (2.7*2.7*0.3) -> 9.477 | Q14: =O14*P14 -> 418.31478 | T14: Floor | U14: =Sources!F75 -> 45.46 | V14: =2.7*2.7 + (2.7*2.7*0.3) -> 9.477 | W14: =U14*V14 -> 430.82442 | Z14: Floor | AA14: =Sources!F96 -> 46.42 | AB14: =2.7*2.7 + (2.7*2.7*0.3) -> 9.477 | AC14: =AA14*AB14 -> 439.92234
B15: Door and roof | C15: =Sources!F13 -> 44.54 | D15: =2.7*2.7 + (2.7*2.7*0.3) -> 9.477 | E15: =C15*D15 -> 422.10558 | H15: Door and roof | I15: =Sources!F34 -> 45.88 | J15: =2.7*2.7 + (2.7*2.7*0.3) -> 9.477 | K15: =I15*J15 -> 434.80476 | N15: Door and roof | O15: =Sources!F55 -> 47.25 | P15: =2.7*2.7 + (2.7*2.7*0.3) -> 9.477 | Q15: =O15*P15 -> 447.78825 | T15: Door and roof | U15: =Sources!F76 -> 48.67 | V15: =2.7*2.7 + (2.7*2.7*0.3) -> 9.477 | W15: =U15*V15 -> 461.24559 | Z15: Door and roof | AA15: =Sources!F97 -> 49.69 | AB15: =2.7*2.7 + (2.7*2.7*0.3) -> 9.477 | AC15: =AA15*AB15 -> 470.91213
B16: Coating | C16: =Sources!F14 -> 63.02 | D16: =2.7*2.7 + (2.7*2.7*0.3) -> 9.477 | E16: =C16*D16 -> 597.24054 | H16: Coating | I16: =Sources!F35 -> 64.91 | J16: =2.7*2.7 + (2.7*2.7*0.3) -> 9.477 | K16: =I16*J16 -> 615.15207 | N16: Coating | O16: =Sources!F56 -> 66.86 | P16: =2.7*2.7 + (2.7*2.7*0.3) -> 9.477 | Q16: =O16*P16 -> 633.63222 | T16: Coating | U16: =Sources!F77 -> 68.86 | V16: =2.7*2.7 + (2.7*2.7*0.3) -> 9.477 | W16: =U16*V16 -> 652.58622 | Z16: Coating | AA16: =Sources!F98 -> 70.31 | AB16: =2.7*2.7 + (2.7*2.7*0.3) -> 9.477 | AC16: =AA16*AB16 -> 666.32787
B17: Toilet | C17: =Sources!F15 -> 41.56 | D17: =2.7*2.7 + (2.7*2.7*0.3) -> 9.477 | E17: =C17*D17 -> 393.86412 | H17: Toilet | I17: =Sources!F36 -> 42.81 | J17: =2.7*2.7 + (2.7*2.7*0.3) -> 9.477 | K17: =I17*J17 -> 405.71037 | N17: Toilet | O17: =Sources!F57 -> 44.09 | P17: =2.7*2.7 + (2.7*2.7*0.3) -> 9.477 | Q17: =O17*P17 -> 417.84093 | T17: Toilet | U17: =Sources!F78 -> 45.41 | V17: =2.7*2.7 + (2.7*2.7*0.3) -> 9.477 | W17: =U17*V17 -> 430.35057 | Z17: Toilet | AA17: =Sources!F99 -> 46.37 | AB17: =2.7*2.7 + (2.7*2.7*0.3) -> 9.477 | AC17: =AA17*AB17 -> 439.44849
B18: Electricals | C18: =Sources!F16 -> 43.82 | D18: =2.7*2.7 + (2.7*2.7*0.3) -> 9.477 | E18: =C18*D18 -> 415.28214 | H18: Electricals | I18: =Sources!F37 -> 45.14 | J18: =2.7*2.7 + (2.7*2.7*0.3) -> 9.477 | K18: =I18*J18 -> 427.79178 | N18: Electricals | O18: =Sources!F58 -> 46.49 | P18: =2.7*2.7 + (2.7*2.7*0.3) -> 9.477 | Q18: =O18*P18 -> 440.58573 | T18: Electricals | U18: =Sources!F79 -> 47.89 | V18: =2.7*2.7 + (2.7*2.7*0.3) -> 9.477 | W18: =U18*V18 -> 453.85353 | Z18: Electricals | AA18: =Sources!F100 -> 48.89 | AB18: =2.7*2.7 + (2.7*2.7*0.3) -> 9.477 | AC18: =AA18*AB18 -> 463.33053
E19: =SUM(E12:E18) -> 5482.4445 | F19: =E19/D18 -> 578.5 | K19: =SUM(K12:K18) -> 5647.06 | Q19: =SUM(Q12:Q18) -> 5816.414 | W19: =SUM(W12:W18) -> 5990.7908 | AC19: =SUM(AC12:AC18) -> 6116.7401
F20: =F19*2 -> 1157
A21: Selva | C21: Unit Cost | D21: Area | E21: Cost | G21: Selva | I21: Unit Cost | J21: Area | K21: Cost | M21: Selva | O21: Unit Cost | P21: Area | Q21: Cost | S21: Selva | U21: Unit Cost | V21: Area | W21: Cost | Y21: Selva | AA21: Unit Cost | AB21: Area | AC21: Cost
A22: 2015 | B22: Walls | C22: =Sources!F17 -> 266.31 | D22: =2.7*2.7 + (2.7*2.7*0.3) -> 9.477 | E22: =C22*D22 -> 2523.8199 | G22: 2016 | H22: Walls | I22: =Sources!F38 -> 274.3 | J22: =2.7*2.7 + (2.7*2.7*0.3) -> 9.477 | K22: =I22*J22 -> 2599.5411 | M22: 2017 | N22: Walls | O22: =Sources!F59 -> 282.53 | P22: =2.7*2.7 + (2.7*2.7*0.3) -> 9.477 | Q22: =O22*P22 -> 2677.5368 | S22: 2018 | T22: Walls | U22: =Sources!F80 -> 291 | V22: =2.7*2.7 + (2.7*2.7*0.3) -> 9.477 | W22: =U22*V22 -> 2757.807 | Y22: 2019 | Z22: Walls | AA22: =Sources!F101 -> 297.11 | AB22: =2.7*2.7 + (2.7*2.7*0.3) -> 9.477 | AC22: =AA22*AB22 -> 2815.7115
B23: Roof | C23: =Sources!F18 -> 144.23 | D23: =2.7*2.7 + (2.7*2.7*0.3) -> 9.477 | E23: =C23*D23 -> 1366.8677 | H23: Roof | I23: =Sources!F39 -> 148.56 | J23: =2.7*2.7 + (2.7*2.7*0.3) -> 9.477 | K23: =I23*J23 -> 1407.9031 | N23: Roof | O23: =Sources!F60 -> 153.02 | P23: =2.7*2.7 + (2.7*2.7*0.3) -> 9.477 | Q23: =O23*P23 -> 1450.1705 | T23: Roof | U23: =Sources!F81 -> 157.61 | V23: =2.7*2.7 + (2.7*2.7*0.3) -> 9.477 | W23: =U23*V23 -> 1493.67 | Z23: Roof | AA23: =Sources!F102 -> 160.92 | AB23: =2.7*2.7 + (2.7*2.7*0.3) -> 9.477 | AC23: =AA23*AB23 -> 1525.0388
B24: Floor | C24: =Sources!F19 -> 47.77 | D24: =2.7*2.7 + (2.7*2.7*0.3) -> 9.477 | E24: =C24*D24 -> 452.71629 | H24: Floor | I24: =Sources!F40 -> 49.21 | J24: =2.7*2.7 + (2.7*2.7*0.3) -> 9.477 | K24: =I24*J24 -> 466.36317 | N24: Floor | O24: =Sources!F61 -> 61.3 | P24: =2.7*2.7 + (2.7*2.7*0.3) -> 9.477 | Q24: =O24*P24 -> 580.9401 | T24: Floor | U24: =Sources!F82 -> 52.2 | V24: =2.7*2.7 + (2.7*2.7*0.3) -> 9.477 | W24: =U24*V24 -> 494.6994 | Z24: Floor | AA24: =Sources!F103 -> 53.3 | AB24: =2.7*2.7 + (2.7*2.7*0.3) -> 9.477 | AC24: =AA24*AB24 -> 505.1241
B25: Door and roof | C25: =Sources!F20 -> 48.02 | D25: =2.7*2.7 + (2.7*2.7*0.3) -> 9.477 | E25: =C25*D25 -> 455.08554 | H25: Door and roof | I25: =Sources!F41 -> 49.46 | J25: =2.7*2.7 + (2.7*2.7*0.3) -> 9.477 | K25: =I25*J25 -> 468.73242 | N25: Door and roof | O25: =Sources!F62 -> 50.95 | P25: =2.7*2.7 + (2.7*2.7*0.3) -> 9.477 | Q25: =O25*P25 -> 482.85315 | T25: Door and roof | U25: =Sources!F83 -> 52.48 | V25: =2.7*2.7 + (2.7*2.7*0.3) -> 9.477 | W25: =U25*V25 -> 497.35296 | Z25: Door and roof | AA25: =Sources!F104 -> 53.58 | AB25: =2.7*2.7 + (2.7*2.7*0.3) -> 9.477 | AC25: =AA25*AB25 -> 507.77766
B26: Coating | C26: =Sources!F21 -> 66.11 | D26: =2.7*2.7 + (2.7*2.7*0.3) -> 9.477 | E26: =C26*D26 -> 626.52447 | H26: Coating | I26: =Sources!F42 -> 68.09 | J26: =2.7*2.7 + (2.7*2.7*0.3) -> 9.477 | K26: =I26*J26 -> 645.28893 | N26: Coating | O26: =Sources!F63 -> 70.14 | P26: =2.7*2.7 + (2.7*2.7*0.3) -> 9.477 | Q26: =O26*P26 -> 664.71678 | T26: Coating | U26: =Sources!F84 -> 72.24 | V26: =2.7*2.7 + (2.7*2.7*0.3) -> 9.477 | W26: =U26*V26 -> 684.61848 | Z26: Coating | AA26: =Sources!F105 -> 73.76 | AB26: =2.7*2.7 + (2.7*2.7*0.3) -> 9.477 | AC26: =AA26*AB26 -> 699.02352
B27: Toilet | C27: =Sources!F22 -> 48.56 | D27: =2.7*2.7 + (2.7*2.7*0.3) -> 9.477 | E27: =C27*D27 -> 460.20312 | H27: Toilet | I27: =Sources!F43 -> 50.02 | J27: =2.7*2.7 + (2.7*2.7*0.3) -> 9.477 | K27: =I27*J27 -> 474.03954 | N27: Toilet | O27: =Sources!F64 -> 51.52 | P27: =2.7*2.7 + (2.7*2.7*0.3) -> 9.477 | Q27: =O27*P27 -> 488.25504 | T27: Toilet | U27: =Sources!F85 -> 53.07 | V27: =2.7*2.7 + (2.7*2.7*0.3) -> 9.477 | W27: =U27*V27 -> 502.94439 | Z27: Toilet | AA27: =Sources!F106 -> 54.18 | AB27: =2.7*2.7 + (2.7*2.7*0.3) -> 9.477 | AC27: =AA27*AB27 -> 513.46386
B28: Electricals | C28: =Sources!F23 -> 53.76 | D28: =2.7*2.7 + (2.7*2.7*0.3) -> 9.477 | E28: =C28*D28 -> 509.48352 | H28: Electricals | I28: =Sources!F44 -> 55.37 | J28: =2.7*2.7 + (2.7*2.7*0.3) -> 9.477 | K28: =I28*J28 -> 524.74149 | N28: Electricals | O28: =Sources!F65 -> 57.03 | P28: =2.7*2.7 + (2.7*2.7*0.3) -> 9.477 | Q28: =O28*P28 -> 540.47331 | T28: Electricals | U28: =Sources!F86 -> 58.74 | V28: =2.7*2.7 + (2.7*2.7*0.3) -> 9.477 | W28: =U28*V28 -> 556.67898 | Z28: Electricals | AA28: =Sources!F107 -> 59.98 | AB28: =2.7*2.7 + (2.7*2.7*0.3) -> 9.477 | AC28: =AA28*AB28 -> 568.43046
E29: =SUM(E22:E28) -> 6394.7005 | K29: =SUM(K22:K28) -> 6586.6098 | Q29: =SUM(Q22:Q28) -> 6884.9457 | W29: =SUM(W22:W28) -> 6987.7712 | AC29: =SUM(AC22:AC28) -> 7134.5699
A31: * add 0.3 of a room to consider passages and services
A32: AVERAGE FOR 2015 | B32: =(E9+E19+E29)/3 -> 5812.1493
A33: INPUT FOR SIM | B33: =B32*1.55 -> 9008.8315
A40: Costa | C40: Unit Cost | D40: Area | E40: Cost
A41: 2015 | B41: Walls | C41: =Sources!F42 -> 68.09 | D41: 210 | E41: =C41*D41 -> 14298.9
B42: Roof | C42: =Sources!F43 -> 50.02 | D42: 210 | E42: =C42*D42 -> 10504.2
B43: Floor | C43: =Sources!F44 -> 55.37 | D43: 210 | E43: =C43*D43 -> 11627.7
B44: Door and roof | C44: =Sources!F45 -> 213.23 | D44: 210 | E44: =C44*D44 -> 44778.3
B45: Coating | C45: =Sources!F46 -> 157.29 | D45: 210 | E45: =C45*D45 -> 33030.9
B46: Toilet | C46: =Sources!F47 -> 36.21 | D46: 210 | E46: =C46*D46 -> 7604.1
B47: Electricals | C47: =Sources!F48 -> 49.98 | D47: 210 | E47: =C47*D47 -> 10495.8
...

Sheet Projections
A1: Region | B1: Year | C1: Projection | D1: Cost | E1: Interannual dif | F1: Inflation | G1: Mean
A2: Costa | B2: 2015 | C2: 5345.4836 | D2: =CalcXsize!E9 -> 5559.303
A3: Costa | B3: 2016 | C3: 5505.9548 | D3: =CalcXsize!K9 -> 5726.1929 | E3: =D3-D2 -> 166.88997 | F3: =E3/D2 -> 0.030019945 | G3: =AVERAGE(F3:F6) -> 0.027751703
A4: Costa | B4: 2017 | C4: 5670.9821 | D4: =CalcXsize!Q9 -> 5897.8214 | E4: =D4-D3 -> 171.62847 | F4: =E4/D3 -> 0.029972527
A5: Costa | B5: 2018 | C5: 5841.2036 | D5: =CalcXsize!W9 -> 6074.8518 | E5: =D5-D4 -> 177.03036 | F5: =E5/D4 -> 0.030016229
A6: Costa | B6: 2019 | C6: 5963.8579 | D6: =CalcXsize!AC9 -> 6202.4122 | E6: =D6-D5 -> 127.56042 | F6: =E6/D5 -> 0.020998112
A7: Costa | B7: 2020 | C7: 6137.0956
A8: Costa | B8: 2021 | C8: 6294.2954
A9: Costa | B9: 2022 | C9: 6451.4951
A10: Costa | B10: 2023 | C10: 6608.6948
A11: Costa | B11: 2024 | C11: 6765.8946
A12: Costa | B12: 2025 | C12: 6923.0943
A13: Costa | B13: 2026 | C13: 7080.294
A14: Costa | B14: 2027 | C14: 7237.4938
A15: Costa | B15: 2028 | C15: 7394.6935
A16: Costa | B16: 2029 | C16: 7551.8933
A17: Costa | B17: 2030 | C17: 7709.093
A18: Costa | B18: 2031 | C18: 7866.2927
... A27: Costa | B27: 2040 | C27: 9281.0904
A28: Sierra | B28: 2015 | C28: 5271.5813 | D28: =CalcXsize!E19 -> 5482.4445
A29: Sierra | B29: 2016 | C29: 5429.8654 | D29: =CalcXsize!K19 -> 5647.06 | E29: =D29-D28 -> 164.61549 | F29: =E29/D28 -> 0.030025929 | G29: =AVERAGE(F29:F32) -> 0.027754909
A30: Sierra | B30: 2017 | C30: 5592.7058 | D30: =CalcXsize!Q19 -> 5816.414 | E30: =D30-D29 -> 169.35399 | F30: =E30/D29 -> 0.029989763
A31: Sierra | B31: 2018 | C31: 5760.3758 | D31: =CalcXsize!W19 -> 5990.7908 | E31: =D31-D30 -> 174.3768 | F31: =E31/D30 -> 0.029980122
A32: Sierra | B32: 2019 | C32: 5881.4809 | D32: =CalcXsize!AC19 -> 6116.7401 | E32: =D32-D31 -> 125.94933 | F32: =E32/D31 -> 0.021023824
A33: Sierra | B33: 2020 | C33: 6052.2947
A34: Sierra | B34: 2021 | C34: 6207.3256
A35: Sierra | B35: 2022 | C35: 6362.3566
A36: Sierra | B36: 2023 | C36: 6517.3876
A37: Sierra | B37: 2024 | C37: 6672.4185
A38: Sierra | B38: 2025 | C38: 6827.4495
A39: Sierra | B39: 2026 | C39: 6982.4805
A40: Sierra | B40: 2027 | C40: 7137.5114
A41: Sierra | B41: 2028 | C41: 7292.5424
A42: Sierra | B42: 2029 | C42: 7447.5733
A43: Sierra | B43: 2030 | C43: 7602.6043
A44: Sierra | B44: 2031 | C44: 7757.6353
... A53: Sierra | B53: 2040 | C53: 9152.9139
A54: Selva | B54: 2015 | C54: 6148.7505 | D54: =CalcXsize!E29 -> 6394.7005
A55: Selva | B55: 2016 | C55: 6333.2786 | D55: =CalcXsize!K29 -> 6586.6098 | E55: =D55-D54 -> 191.90925 | F55: =E55/D54 -> 0.03001067 | G55: =AVERAGE(F55:F58) -> 0.027811938
A56: Selva | B56: 2017 | C56: 6620.1401 | D56: =CalcXsize!Q29 -> 6884.9457 | E56: =D56-D55 -> 298.33596 | F56: =E56/D55 -> 0.045294312
...
